<?xml version = "1.0" ?>
<robot name="biped" xmlns:xacro="http://www.ros.org/wiki/xacro">

<!-- revolute joints -->
<joint name="LEFT_HIP_X" type="revolute">
    <origin rpy="0 0 0" xyz="0.055 0.0935 0.02" />
    <axis xyz="0 0 -1" />
    <parent link="BODY_LINK" />
    <child link="LEFT_HIP_LINK" />
    <limit effort="1000" lower="-0.7854" upper="0.7854" velocity = "100" />
    <dynamics damping="0.05" friction="0.0"/>
</joint>

<joint name="RIGHT_HIP_X" type="revolute">
    <origin rpy="0 0 0" xyz="0.055 -0.093 0.02" />
    <axis xyz="0 0 -1" />
    <parent link="BODY_LINK" />
    <child link="RIGHT_HIP_LINK" />
    <limit effort="1000" lower="-0.7854" upper="0.7854" velocity = "100" />
    <dynamics damping="0.05" friction="0.0"/>
</joint>

<joint name="LEFT_THIGH_Y" type="revolute">
    <origin rpy="0 0 0" xyz="-0.06 0.0345 0.0" />
    <axis xyz="1 0 0" />
    <parent link="LEFT_HIP_LINK" />
    <child link="LEFT_THIGH_LINK" />
    <limit effort="1000" lower="-0.5236" upper="1.0472" velocity = "100" />
    <dynamics damping="0.05" friction="0.0"/>
</joint>

<joint name="RIGHT_THIGH_Y" type="revolute">
    <origin rpy="0 0 0" xyz="-0.06 -0.0345 0.0" />
    <axis xyz="1 0 0" />
    <parent link="RIGHT_HIP_LINK" />
    <child link="RIGHT_THIGH_LINK" />
    <limit effort="1000" lower="-1.0472" upper="0.5236" velocity = "100" />
    <dynamics damping="0.05" friction="0.0"/>
</joint>

<joint name="LEFT_KNEE_Y" type="revolute">
    <origin rpy="0 0 0" xyz="0 0 -0.3" />
    <axis xyz="0 1 0" />
    <parent link="LEFT_THIGH_LINK" />
    <child link="LEFT_SHIN_LINK" />
    <limit effort="1000" lower="-1.57" upper="0.314" velocity = "100" />
    <dynamics damping="0.05" friction="0.0"/>
</joint>

<joint name='RIGHT_KNEE_Y' type='revolute'>
    <origin rpy="0 0 0" xyz="0 0 -0.3" />
    <axis xyz="0 1 0" />
    <parent link="RIGHT_THIGH_LINK" />
    <child link="RIGHT_SHIN_LINK" />
    <limit effort="350" lower="0" upper="2.62" velocity = "100" />
    <dynamics damping="0.05" friction="0.0"/>
</joint>

<!-- links -->
<link name="BODY_LINK">
  <inertial>
    <mass value="1.404"/>
    <origin rpy="0 0 0" xyz="-0.00115 0.0 0.05486"/>
    <inertia ixx="0.00503" ixy="0.0" ixz="-0.00107" iyy="0.00499" iyz="0.0" izz="0.00431" />
  </inertial>
  <visual>
    <geometry>
      <mesh filename="package://biped_model/body.STL"/>
    </geometry>
    <origin rpy="0.0 0.0 0.0" xyz="0.0 0.0 0.0"/>
  </visual>
</link>

<link name="LEFT_HIP_LINK">
  <inertial>
    <mass value="0.196"/>
    <origin rpy="0 0 0" xyz="-0.06 0.0 0.0"/>
    <inertia ixx="0.000052224" ixy="0.0" ixz="0.0" iyy="0.000261120" iyz="0.0" izz="0.000261120" />
  </inertial>
  <visual>
    <geometry>
      <mesh filename="package://biped_model/hip.STL"/>
    </geometry>
    <origin rpy="0.0 0.0 0.0" xyz="0.0 0.0 0.0"/>
  </visual>
</link>

<link name="RIGHT_HIP_LINK">
  <inertial>
    <mass value="0.196"/>
    <origin rpy="0 0 0" xyz="-0.06 0.0 0.0"/>
    <inertia ixx="0.000052224" ixy="0.0" ixz="0.0" iyy="0.000261120" iyz="0.0" izz="0.000261120" />
  </inertial>
  <visual>
    <geometry>
      <mesh filename="package://biped_model/hip.STL"/>
    </geometry>
    <origin rpy="0.0 0.0 0.0" xyz="0.0 0.0 0.0"/>
  </visual>
</link>

<link name="LEFT_THIGH_LINK">
  <inertial>
    <mass value="0.306"/>
    <origin rpy="0 0 0" xyz="0.0 0.0 -0.015"/>
    <inertia ixx="0.0091959375" ixy="0.0" ixz="0.0" iyy="0.0092208" iyz="0.0" izz="0.0000567375" />
  </inertial>
  <visual>
    <geometry>
      <mesh filename="package://biped_model/thigh.STL"/>
    </geometry>
    <origin rpy="0.0 0.0 0.0" xyz="0.0 0.0 0.0"/>
  </visual>
</link>

<link name="RIGHT_THIGH_LINK">
  <inertial>
    <mass value="0.306"/>
    <origin rpy="0 0 0" xyz="0.0 0.0 -0.015"/>
    <inertia ixx="0.0091959375" ixy="0.0" ixz="0.0" iyy="0.0092208" iyz="0.0" izz="0.0000567375" />
  </inertial>
  <visual>
    <geometry>
      <mesh filename="package://biped_model/thigh.STL"/>
    </geometry>
    <origin rpy="0.0 0.0 0.0" xyz="0.0 0.0 0.0"/>
  </visual>
</link>

<link name="LEFT_SHIN_LINK">
  <inertial>
    <mass value="10.953"/>
    <origin rpy="0 0 0" xyz="0.0 0.0 -0.12218"/>
    <inertia ixx="0.0014311516" ixy="-0.19E-9" ixz="0.12E-9" iyy="0.00143198183" iyz="-0.17E-9" izz="2.79931E-6" />
  </inertial>
  <visual>
    <geometry>
      <mesh filename="package://biped_model/shin.STL"/>
    </geometry>
    <origin rpy="0.0 0.0 0.0" xyz="0.0 0.0 0.0"/>
  </visual>
</link>

<link name="RIGHT_SHIN_LINK">
  <inertial>
    <mass value="10.953"/>
    <origin rpy="0 0 0" xyz="0.0 0.0 -0.12218"/>
    <inertia ixx="0.0014311516" ixy="-0.19E-9" ixz="0.12E-9" iyy="0.00143198183" iyz="-0.17E-9" izz="2.79931E-6" />
  </inertial>
  <visual>
    <geometry>
      <mesh filename="package://biped_model/shin.STL"/>
    </geometry>
    <origin rpy="0.0 0.0 0.0" xyz="0.0 0.0 0.0"/>
  </visual>
</link>

</robot>