<?xml version = "1.0" ?>
<robot name="biped" xmlns:xacro="http://www.ros.org/wiki/xacro">

<!-- revolute joints -->
<joint name="LEFT_HIP_X" type="revolute">
    <origin rpy="0 0 0" xyz="0 0.115 -0.07185" />
    <axis xyz="0 0 -1" />
    <parent link="BODY_LINK" />
    <child link="LEFT_HIP_LINK" />
    <limit effort="1000" lower="-0.7854" upper="0.7854" velocity = "100" />
    <dynamics damping="0.05" friction="0.0"/>
</joint>

<joint name="RIGHT_HIP_X" type="revolute">
    <origin rpy="0 0 0" xyz="0 -0.115 -0.07185" />
    <axis xyz="0 0 -1" />
    <parent link="BODY_LINK" />
    <child link="RIGHT_HIP_LINK" />
    <limit effort="1000" lower="-0.7854" upper="0.7854" velocity = "100" />
    <dynamics damping="0.05" friction="0.0"/>
</joint>

<joint name="LEFT_THIGH_Y" type="revolute">
    <origin rpy="0 0 0" xyz="0.035 0.015 -0.04975" />
    <axis xyz="1 0 0" />
    <parent link="LEFT_HIP_LINK" />
    <child link="LEFT_THIGH_LINK" />
    <limit effort="1000" lower="-0.5236" upper="1.0472" velocity = "100" />
    <dynamics damping="0.05" friction="0.0"/>
</joint>

<joint name="RIGHT_THIGH_Y" type="revolute">
    <origin rpy="0 0 0" xyz="0.035 -0.015 -0.04975" />
    <axis xyz="1 0 0" />
    <parent link="RIGHT_HIP_LINK" />
    <child link="RIGHT_THIGH_LINK" />
    <limit effort="1000" lower="-1.0472" upper="0.5236" velocity = "100" />
    <dynamics damping="0.05" friction="0.0"/>
</joint>

<joint name="LEFT_KNEE_Y" type="revolute">
    <origin rpy="0 0 0" xyz="0 0 -0.079068" />
    <axis xyz="0 1 0" />
    <parent link="LEFT_THIGH_LINK" />
    <child link="LEFT_SHIN_LINK" />
    <limit effort="1000" lower="-1.57" upper="0.314" velocity = "100" />
    <dynamics damping="0.05" friction="0.0"/>
</joint>

<joint name='RIGHT_KNEE_Y' type='revolute'>
    <origin rpy="0 0 0" xyz="0 0 -0.38" />
    <axis xyz="0 1 0" />
    <parent link="RIGHT_THIGH_LINK" />
    <child link="RIGHT_SHIN_LINK" />
    <limit effort="350" lower="0" upper="2.62" velocity = "100" />
    <dynamics damping="0.05" friction="0.0"/>
</joint>

<!-- links -->
<link name="BODY_LINK">
  <inertial>
    <mass value="19.0917"/>
    <origin rpy="0 0 0" xyz="0.02073086 2.023E-05 -0.0309812"/>
    <inertia ixx="0.0942" ixy="6.05E-06" ixz="0.000379" iyy="0.0416" iyz="3.37E-07" izz="0.112" />
  </inertial>
  <visual>
    <geometry>
      <mesh filename="package://biped_model/body.STL"/>
    </geometry>
    <origin rpy="0.0 0.0 0.0" xyz="0.0 0.0 0.0"/>
  </visual>
</link>

<link name="LEFT_HIP_LINK">
  <inertial>
    <mass value="1.814"/>
    <origin rpy="0 0 0" xyz="-0.00629727 0.00606893 -0.03971844"/>
    <inertia ixx="0.004741914" ixy="0.000527" ixz="-0.000307" iyy="0.00414" iyz="1.36E-05" izz="0.00569" />
  </inertial>
  <visual>
    <geometry>
      <mesh filename="package://biped_model/hip.obj"/>
    </geometry>
    <origin rpy="0.0 0.0 0.0" xyz="0.0 0.0 0.0"/>
  </visual>
</link>

<link name="RIGHT_HIP_LINK">
  <inertial>
    <mass value="1.814"/>
    <origin rpy="0 0 0" xyz="-0.00629727 -0.00606893 -0.03971844"/>
    <inertia ixx="0.004741914" ixy="-0.000527" ixz="-0.000307" iyy="0.00414" iyz="-1.36E-05" izz="0.00569" />
  </inertial>
  <visual>
    <geometry>
      <mesh filename="package://biped_model/hip.obj"/>
    </geometry>
    <origin rpy="0.0 0.0 0.0" xyz="0.0 0.0 0.0"/>
  </visual>
</link>

<link name="LEFT_THIGH_LINK">
  <inertial>
    <mass value="0.762"/>
    <origin rpy="0 0 0" xyz="-0.01327037 0.00316985 -0.05399997"/>
    <inertia ixx="0.001028994" ixy="-9.31E-06" ixz="0.000352" iyy="0.00138" iyz="3.22E-05" izz="0.000663" />
  </inertial>
  <visual>
    <geometry>
      <mesh filename="package://biped_model/thigh.obj"/>
    </geometry>
    <origin rpy="0.0 0.0 0.0" xyz="0.0 0.0 0.0"/>
  </visual>
</link>

<link name="RIGHT_THIGH_LINK">
  <inertial>
    <mass value="0.762"/>
    <origin rpy="0 0 0" xyz="-0.01327037 -0.00316985 -0.05399997"/>
    <inertia ixx="0.001028994" ixy="9.31E-06" ixz="0.000352" iyy="0.00138" iyz="-3.22E-05" izz="0.000663" />
  </inertial>
  <visual>
    <geometry>
      <mesh filename="package://biped_model/thigh.obj"/>
    </geometry>
    <origin rpy="0.0 0.0 0.0" xyz="0.0 0.0 0.0"/>
  </visual>
</link>

<link name="LEFT_SHIN_LINK">
  <inertial>
    <mass value="10.953"/>
    <origin rpy="0 0 0" xyz="-0.00093749 0.01134511 -0.17863144"/>
    <inertia ixx="0.1622268263" ixy="-0.000749" ixz="0.0156" iyy="0.174" iyz="0.00213" izz="0.0528" />
  </inertial>
  <visual>
    <geometry>
      <mesh filename="package://biped_model/shin.obj"/>
    </geometry>
    <origin rpy="0.0 0.0 0.0" xyz="0.0 0.0 0.0"/>
  </visual>
</link>

<link name="RIGHT_SHIN_LINK">
  <inertial>
    <mass value="10.953"/>
    <origin rpy="0 0 0" xyz="-0.00093749 -0.01134511 -0.17863144"/>
    <inertia ixx="0.1622268263" ixy="0.000749" ixz="0.0156" iyy="0.174" iyz="-0.00213" izz="0.0528" />
  </inertial>
  <visual>
    <geometry>
      <mesh filename="package://biped_model/shin.obj"/>
    </geometry>
    <origin rpy="0.0 0.0 0.0" xyz="0.0 0.0 0.0"/>
  </visual>
</link>

</robot>